Workbook

Sheet Как читать
A1: Экономика SevastopolAI · City Code · YuRichRWA — v1.1 от 2026-10-25
A2: Источник правды — economics/params.json. Этот файл собирается скриптом economics/build_model.py.
A3: Жёлтое — вводные (можно менять здесь, но потом перенеси в params.json). Зелёное — итоги. Всё остальное — формулы.
A4: Проверка: python tools/check.py — пересчитывает этот файл независимым движком и сверяет с economics/model.py до копейки.
A5: Оборот партнёров ≠ наша выручка. Сценарии — модель, не факт. Зарплата основателя не учтена.
A7: Листы: Параметры → Расчёт (юнит-экономика до копейки) → Сценарии S1–S5 → XP → Доли партнёров.

Sheet Параметры
A1: Ключ | B1: Параметр | C1: Ед. | D1: Значение | E1: Статус | F1: Источник
B2: City Code · членство
A3: price_basic | B3: Basic, в год | C3: ₽ | D3: 5108 | E3: решение | F3: City Code v1.0, п.3
A4: price_founder | B4: «Основатели», в год | C4: ₽ | D4: 15108 | E4: решение | F4: City Code v1.0, п.3
A5: seats_basic | B5: Мест Basic в первом транше | C5: шт | D5: 250 | E5: решение | F5: v1.0, п.4
A6: seats_founder | B6: Мест «Основатели» в первом транше | C6: шт | D6: 50 | E6: решение | F6: v1.0, п.4
A7: days_year | B7: Дней в году членства | C7: дн | D7: 365 | E7: факт | F7: срок 12 месяцев, v1.0
A8: partners_signed | B8: Подписано партнёров сейчас | C8: шт | D8: 0 | E8: допущение | F8: обновляй после каждого подписания
A9: refund_days_used | B9: Пример возврата: прошло дней | C9: дн | D9: 90 | E9: допущение | F9: пример для оферты
B10: Расход участника и привилегии
A11: spend | B11: Средний расход участника у партнёров | C11: ₽/мес | D11: 7000 | E11: допущение | F11: v1.0, п.6 — проверить отчётами партнёров
A12: priv_min | B12: Привилегия минимум | C12: % | D12: 0.03 | E12: решение | F12: v1.0, п.5
A13: priv_avg | B13: Привилегия в среднем | C13: % | D13: 0.05 | E13: допущение | F13: середина 3–7%
A14: priv_max | B14: Привилегия максимум | C14: % | D14: 0.07 | E14: решение | F14: v1.0, п.5
B15: Партнёр
A16: partner_fee | B16: Вход партнёра в первом транше | C16: ₽ | D16: 0 | E16: решение | F16: v1.0, п.5: без платы за вход и без комиссии
A17: partner_turnover | B17: Допустимый доп. оборот партнёра от клуба | C17: ₽/мес | D17: 105000 | E17: допущение | F17: спросить у партнёра при подписании; 105 000 = 15 мест
A18: partner_margin | B18: Маржинальность партнёра (выручка минус себестоимость) | C18: % | D18: 0.6 | E18: допущение | F18: кафе ~60–70%, розница ~30% — подставь своё
A19: partner_new_share | B19: Доля клубного оборота, которой без клуба не было бы | C19: % | D19: 0.3 | E19: допущение | F19: проверить на пилоте
A20: partner_exit_days | B20: Уведомление о выходе партнёра | C20: дн | D20: 14 | E20: решение | F20: v1.1
B21: Налоги и приём платежей
A22: npd_ind | B22: НПД с физлиц | C22: % | D22: 0.04 | E22: факт | F22: 422-ФЗ; ставки 2026 не менялись (naloger.ru, kontur.ru)
A23: npd_biz | B23: НПД с ИП и юрлиц | C23: % | D23: 0.06 | E23: факт | F23: 422-ФЗ
A24: npd_limit | B24: Лимит дохода НПД | C24: ₽/год | D24: 2400000 | E24: факт | F24: 422-ФЗ, п.8 ч.2 ст.4; режим до 31.12.2028
A25: usn | B25: УСН «доходы» | C25: % | D25: 0.06 | E25: факт | F25: НК РФ ст.346.20
A26: ip_fixed | B26: Фикс. взносы ИП за себя, 2026 | C26: ₽/год | D26: 57390 | E26: факт | F26: nalog.gov.ru, ст.430 НК
A27: ip_extra | B27: Доп. взнос ИП с дохода сверх 300 000 | C27: % | D27: 0.01 | E27: факт | F27: ст.430 НК
A28: ip_extra_from | B28: Порог доп. взноса | C28: ₽/год | D28: 300000 | E28: факт | F28: ст.430 НК
A29: acq_sbp | B29: СБП (потолок ЦБ для бизнеса) | C29: % | D29: 0.007 | E29: факт | F29: ЦБ: не выше 0,7%; НДС на перевод не начисляется
A30: acq_card | B30: Карты через ЮKassa (базовый тариф) | C30: % | D30: 0.035 | E30: факт | F30: yookassa.ru/docs/support/payments/fees
A31: acq_vat | B31: НДС на комиссию за карты с 2026 | C31: % | D31: 0.22 | E31: факт | F31: 425-ФЗ; ЮKassa удерживает 22% от комиссии
A32: sbp_share | B32: Доля оплат по СБП | C32: % | D32: 0.5 | E32: допущение | F32: проси платить по СБП — это дешевле в 6 раз
A33: ad_levy | B33: Отчисление с интернет-рекламы | C33: % | D33: 0.03 | E33: факт | F33: ст.18.2 «О рекламе», с 01.04.2025
B34: Мерч (себестоимость — оценка, уточнить у подрядчика)
A35: passport_price | B35: Физический паспорт, цена | C35: ₽ | D35: 1500 | E35: решение | F35: прайс v1.0-документа
A36: passport_cost | B36: Физический паспорт, себестоимость | C36: ₽ | D36: 400 | E36: допущение | F36: оценка, запросить у типографии
A37: keychain_price | B37: Брелок «6 ключей», цена | C37: ₽ | D37: 1200 | E37: решение
A38: keychain_cost | B38: Брелок, себестоимость | C38: ₽ | D38: 425 | E38: допущение | F38: середина 350–500
A39: hoodie_price | B39: Худи, цена | C39: ₽ | D39: 4900 | E39: решение
A40: hoodie_cost | B40: Худи, себестоимость | C40: ₽ | D40: 2250 | E40: допущение | F40: середина 2 000–2 500
...

Sheet Расчёт
A1: Ключ | B1: Показатель | C1: Ед. | D1: Значение | E1: Как считается | F1: Формула
B2: Членство: цена в день, комиссия, налог, сколько остаётся
A3: basic_month | B3: Basic в месяц | C3: ₽ | D3: =ROUND('Параметры'!$D$3/12,2) | E3: цена ÷ 12 | F3: ROUND({price_basic}/12,2)
A4: basic_day | B4: Basic в день | C4: ₽ | D4: =ROUND('Параметры'!$D$3/'Параметры'!$D$7,2) | E4: цена ÷ 365 | F4: ROUND({price_basic}/{days_year},2)
A5: founder_month | B5: «Основатели» в месяц | C5: ₽ | D5: =ROUND('Параметры'!$D$4/12,2) | E5: цена ÷ 12 | F5: ROUND({price_founder}/12,2)
A6: founder_day | B6: «Основатели» в день | C6: ₽ | D6: =ROUND('Параметры'!$D$4/'Параметры'!$D$7,2) | E6: цена ÷ 365 | F6: ROUND({price_founder}/{days_year},2)
A7: acq_card_eff | B7: Карты: комиссия с НДС | C7: % | D7: ='Параметры'!$D$30*(1+'Параметры'!$D$31) | E7: 3,5% × 1,22 | F7: {acq_card}*(1+{acq_vat})
A8: acq_blend | B8: Комиссия в среднем (доля СБП из параметров) | C8: % | D8: ='Параметры'!$D$32*'Параметры'!$D$29+(1-'Параметры'!$D$32)*$D$7 | E8: смесь СБП и карт | F8: {sbp_share}*{acq_sbp}+(1-{sbp_share})*{acq_card_eff}
A9: basic_fee_sbp | B9: Basic: комиссия СБП | C9: ₽ | D9: =ROUND('Параметры'!$D$3*'Параметры'!$D$29,2) | E9: 5 108 × 0,7% | F9: ROUND({price_basic}*{acq_sbp},2)
A10: basic_fee_card | B10: Basic: комиссия карты | C10: ₽ | D10: =ROUND('Параметры'!$D$3*$D$7,2) | E10: 5 108 × 4,27% | F10: ROUND({price_basic}*{acq_card_eff},2)
A11: basic_tax_npd | B11: Basic: налог НПД 4% | C11: ₽ | D11: =ROUND('Параметры'!$D$3*'Параметры'!$D$22,2) | E11: с полной суммы | F11: ROUND({price_basic}*{npd_ind},2)
A12: basic_tax_usn | B12: Basic: налог УСН 6% (если ИП) | C12: ₽ | D12: =ROUND('Параметры'!$D$3*'Параметры'!$D$25,2) | E12: до вычета взносов | F12: ROUND({price_basic}*{usn},2)
A13: basic_net_npd_sbp | B13: Basic: остаётся (НПД + СБП) | C13: ₽ | D13: ='Параметры'!$D$3-$D$9-$D$11 | E13: основной вариант | F13: {price_basic}-{basic_fee_sbp}-{basic_tax_npd}
A14: basic_net_npd_card | B14: Basic: остаётся (НПД + карта) | C14: ₽ | D14: ='Параметры'!$D$3-$D$10-$D$11 | E14: если платят картой | F14: {price_basic}-{basic_fee_card}-{basic_tax_npd}
A15: basic_net_usn_sbp | B15: Basic: остаётся (ИП УСН + СБП) | C15: ₽ | D15: ='Параметры'!$D$3-$D$9-$D$12 | E15: после перехода на ИП | F15: {price_basic}-{basic_fee_sbp}-{basic_tax_usn}
A16: founder_kit_cost | B16: «Основатели»: себестоимость набора (паспорт + брелок) | C16: ₽ | D16: ='Параметры'!$D$36+'Параметры'!$D$38 | E16: выдаём физически | F16: {passport_cost}+{keychain_cost}
A17: founder_kit_retail | B17: «Основатели»: набор по рознице | C17: ₽ | D17: ='Параметры'!$D$35+'Параметры'!$D$37 | E17: что человек получает в рублях | F17: {passport_price}+{keychain_price}
A18: founder_fee_sbp | B18: «Основатели»: комиссия СБП | C18: ₽ | D18: =ROUND('Параметры'!$D$4*'Параметры'!$D$29,2) | F18: ROUND({price_founder}*{acq_sbp},2)
A19: founder_tax_npd | B19: «Основатели»: налог НПД 4% | C19: ₽ | D19: =ROUND('Параметры'!$D$4*'Параметры'!$D$22,2) | F19: ROUND({price_founder}*{npd_ind},2)
A20: founder_net_npd_sbp | B20: «Основатели»: остаётся (НПД + СБП − набор) | C20: ₽ | D20: ='Параметры'!$D$4-$D$18-$D$19-$D$16 | F20: {price_founder}-{founder_fee_sbp}-{founder_tax_npd}-{founder_kit_cost}
A21: founder_extra | B21: «Основатели» дороже Basic на | C21: ₽ | D21: ='Параметры'!$D$4-'Параметры'!$D$3 | F21: {price_founder}-{price_basic}
A22: tranche_seats | B22: Мест в транше | C22: шт | D22: ='Параметры'!$D$5+'Параметры'!$D$6 | E22: 250 + 50 | F22: {seats_basic}+{seats_founder}
A23: tranche_gross | B23: Транш: выручка | C23: ₽ | D23: ='Параметры'!$D$5*'Параметры'!$D$3+'Параметры'!$D$6*'Параметры'!$D$4 | E23: 250 × 5 108 + 50 × 15 108 | F23: {seats_basic}*{price_basic}+{seats_founder}*{price_founder}
A24: tranche_net_npd_sbp | B24: Транш: остаётся (НПД + СБП − наборы) | C24: ₽ | D24: ='Параметры'!$D$5*$D$13+'Параметры'!$D$6*$D$20 | F24: {seats_basic}*{basic_net_npd_sbp}+{seats_founder}*{founder_net_npd_sbp}
A25: npd_headroom | B25: Запас до лимита НПД в год продажи транша | C25: ₽ | D25: ='Параметры'!$D$24-$D$23 | E25: всё сверх — уже ИП | F25: {npd_limit}-{tranche_gross}
A26: v10_typo | B26: Ошибка годовой модели v1.0 (300 × 5 108) | C26: ₽ | D26: =$D$23-$D$22*'Параметры'!$D$3 | E26: v1.0 недосчитал | F26: {tranche_gross}-{tranche_seats}*{price_basic}
B27: Честно для участника: сколько возвращают привилегии
A28: saving_min | B28: Экономия в год при 3% | C28: ₽ | D28: ='Параметры'!$D$11*12*'Параметры'!$D$12 | E28: 7 000 × 12 × 3% | F28: {spend}*12*{priv_min}
A29: saving_avg | B29: Экономия в год при 5% | C29: ₽ | D29: ='Параметры'!$D$11*12*'Параметры'!$D$13 | E29: 7 000 × 12 × 5% | F29: {spend}*12*{priv_avg}
A30: saving_max | B30: Экономия в год при 7% | C30: ₽ | D30: ='Параметры'!$D$11*12*'Параметры'!$D$14 | E30: 7 000 × 12 × 7% | F30: {spend}*12*{priv_max}
A31: payback_avg | B31: Привилегии при 5% возвращают от цены Basic | C31: % | D31: =ROUND($D$29/'Параметры'!$D$3,4) | E31: остальное — события и люди | F31: ROUND({saving_avg}/{price_basic},4)
A32: breakeven_min | B32: Basic окупается привилегиями при расходе (3%) | C32: ₽ | D32: =ROUND('Параметры'!$D$3/12/'Параметры'!$D$12,2) | E32: в месяц | F32: ROUND({price_basic}/12/{priv_min},2)
A33: breakeven_avg | B33: Basic окупается привилегиями при расходе (5%) | C33: ₽ | D33: =ROUND('Параметры'!$D$3/12/'Параметры'!$D$13,2) | E33: в месяц | F33: ROUND({price_basic}/12/{priv_avg},2)
A34: breakeven_max | B34: Basic окупается привилегиями при расходе (7%) | C34: ₽ | D34: =ROUND('Параметры'!$D$3/12/'Параметры'!$D$14,2) | E34: в месяц | F34: ROUND({price_basic}/12/{priv_max},2)
A35: founder_breakeven_avg | B35: «Основатели» окупаются привилегиями при расходе (5%) | C35: ₽ | D35: =ROUND('Параметры'!$D$4/12/'Параметры'!$D$13,2) | E35: в месяц — это статус, не скидка | F35: ROUND({price_founder}/12/{priv_avg},2)
B36: Честно для партнёра: что стоит привилегия и что даёт клуб
A37: seats_per_partner | B37: Мест на одного партнёра | C37: шт | D37: =FLOOR('Параметры'!$D$17/'Параметры'!$D$11,1) | E37: доп. оборот ÷ расход участника (правило v1.0) | F37: FLOOR({partner_turnover}/{spend},1)
A38: partner_priv_cost | B38: Партнёр отдаёт привилегией в месяц | C38: ₽ | D38: ='Параметры'!$D$17*'Параметры'!$D$13 | E38: оборот × 5% | F38: {partner_turnover}*{priv_avg}
A39: partner_new_profit | B39: Партнёр получает маржи с новых гостей в месяц | C39: ₽ | D39: ='Параметры'!$D$17*'Параметры'!$D$19*'Параметры'!$D$18 | E39: оборот × доля новых × маржа | F39: {partner_turnover}*{partner_new_share}*{partner_margin}
A40: partner_gain | B40: Итог партнёра в месяц | C40: ₽ | D40: =$D$39-$D$38 | F40: {partner_new_profit}-{partner_priv_cost}
...

Sheet Сценарии
A1: Сценарии роста. Жёлтое — вводные сценария; цены, налоги и комиссии берутся из «Параметры» и «Расчёт».
A3: Показатель | B3: Ед. | C3: S1 · Пилот | D3: S2 · Сеть | E3: S3 · Город | F3: S4 · Зрелый город | G3: S5 · 3 города
C4: 5 партнёров · 100 MAU | D4: 10 партнёров · 500 MAU | E4: 30 партнёров · 5 000 MAU | F4: 60 партнёров · 15 000 MAU | G4: 150 партнёров · 50 000 MAU
A5: ВВОДНЫЕ СЦЕНАРИЯ
A6: Партнёров (точек) | B6: шт | C6: 5 | D6: 10 | E6: 30 | F6: 60 | G6: 150
A7: Пользователей бота в месяц (MAU) | B7: чел | C7: 100 | D7: 500 | E7: 5000 | F7: 15000 | G7: 50000
A8: Мест «Основатели» всего | B8: шт | C8: 50 | D8: 50 | E8: 50 | F8: 50 | G8: 150 | H8: 50 на город
A9: Конверсия MAU → участник | B9: % | C9: 0.05 | D9: 0.04 | E9: 0.035 | F9: 0.03 | G9: 0.03 | H9: проверить на пилоте
A10: Участники из личных продаж | B10: чел | C10: 10 | D10: 30 | E10: 60 | F10: 80 | G10: 150 | H10: Основатели продаются руками
A11: Взнос партнёра v2.0 (не принято — решение владельца) | B11: ₽/мес | C11: 0 | D11: 0 | E11: 3000 | F11: 3000 | G11: 3000 | H11: v1.0 разрешает «в последующих версиях»; вводить только после отчёта, что партнёр в плюсе
A12: Платных размещений SAI в месяц | B12: шт | C12: 2 | D12: 5 | E12: 12 | F12: 20 | G12: 40 | H12: не чаще 1 рекламы на 6–8 своих постов
A13: Охват поста | B13: просм. | C13: 800 | D13: 1500 | E13: 4000 | F13: 8000 | G13: 15000 | H13: ≈25–30% подписчиков канала; цена = охват × CPM, не ниже минимума
A14: Доля размещений от партнёров (−50%) | B14: % | C14: 0.5 | D14: 0.5 | E14: 0.5 | F14: 0.5 | G14: 0.5
A15: Съёмок в месяц | B15: шт | C15: 0 | D15: 2 | E15: 4 | F15: 8 | G15: 20
A16: Платных событий в месяц | B16: шт | C16: 0 | D16: 1 | E16: 2 | F16: 4 | G16: 10
A17: Гостей на событии | B17: чел | C17: 0 | D17: 20 | E17: 35 | F17: 50 | G17: 50
A18: Билет | B18: ₽ | C18: 1500 | D18: 1500 | E18: 2000 | F18: 2000 | G18: 2000
A19: Себестоимость событий (вкл. 50% площадке) | B19: % | C19: 0.65 | D19: 0.65 | E19: 0.65 | F19: 0.65 | G19: 0.65
A20: Доля участников, купивших мерч в месяц | B20: % | C20: 0.03 | D20: 0.03 | E20: 0.03 | F20: 0.03 | G20: 0.03
A21: Доля MAU, купивших мерч в месяц | B21: % | C21: 0.001 | D21: 0.001 | E21: 0.001 | F21: 0.001 | G21: 0.001
A22: Средний чек мерча | B22: ₽ | C22: 2500 | D22: 2500 | E22: 2500 | F22: 2500 | G22: 2500
A23: Себестоимость мерча | B23: % | C23: 0.45 | D23: 0.45 | E23: 0.45 | F23: 0.45 | G23: 0.45
A24: Разборов ЦФА в год (80 000 ₽) | B24: шт | C24: 1 | D24: 2 | E24: 4 | F24: 6 | G24: 10 | H24: личная экспертиза, отдельный контур
A25: Сборок выпуска в год (325 000 ₽) | B25: шт | C25: 0 | D25: 1 | E25: 2 | F25: 3 | G25: 5 | H25: середина 250–400 тыс.
A26: Подписчиков YuRichRWA | B26: чел | C26: 1000 | D26: 2000 | E26: 5000 | F26: 10000 | G26: 20000
A27: Охват поста YuRichRWA | B27: % | C27: 0.3 | D27: 0.3 | E27: 0.3 | F27: 0.3 | G27: 0.3
A28: CPM ниши RWA | B28: ₽ | C28: 1500 | D28: 1500 | E28: 1500 | F28: 1500 | G28: 1500
A29: Рекламных постов YuRichRWA в месяц | B29: шт | C29: 0 | D29: 1 | E29: 3 | F29: 5 | G29: 8
A30: Сервер, домены, сервисы | B30: ₽/мес | C30: 1500 | D30: 2500 | E30: 6000 | F30: 15000 | G30: 40000
A31: AI (Кира) на 1 MAU | B31: ₽ | C31: 0 | D31: 0 | E31: 3 | F31: 3 | G31: 3 | H31: с S3
A32: Команда | B32: ₽/мес | C32: 0 | D32: 30000 | E32: 140000 | F32: 400000 | G32: 1200000 | H32: S1 — всё сам
A33: Маркетинг: посевы, QR, печать | B33: ₽/мес | C33: 10000 | D33: 30000 | E33: 100000 | F33: 200000 | G33: 600000
A34: Бухгалтерия и юрист | B34: ₽/мес | C34: 5000 | D34: 10000 | E34: 20000 | F34: 40000 | G34: 100000
A35: Товарный знак, ПО, БД (разово / 12) | B35: ₽/мес | C35: 12500 | D35: 12500 | E35: 0 | F35: 0 | G35: 25000
A36: Часы на контент | B36: ч | C36: 20 | D36: 30 | E36: 60 | F36: 100 | G36: 250
A37: CITY CODE
A38: Спрос на членство | B38: чел | C38: =C7*C9+C10 | D38: =D7*D9+D10 | E38: =E7*E9+E10 | F38: =F7*F9+F10 | G38: =G7*G9+G10
A39: Потолок по партнёрам (15 на точку) | B39: чел | C39: =C6*'Расчёт'!$D$37 | D39: =D6*'Расчёт'!$D$37 | E39: =E6*'Расчёт'!$D$37 | F39: =F6*'Расчёт'!$D$37 | G39: =G6*'Расчёт'!$D$37
A40: Участников | B40: чел | C40: =ROUND(MIN(C38,C39),0) | D40: =ROUND(MIN(D38,D39),0) | E40: =ROUND(MIN(E38,E39),0) | F40: =ROUND(MIN(F38,F39),0) | G40: =ROUND(MIN(G38,G39),0)
A41: из них «Основатели» | B41: чел | C41: =MIN(C8,C40) | D41: =MIN(D8,D40) | E41: =MIN(E8,E40) | F41: =MIN(F8,F40) | G41: =MIN(G8,G40)
...

Sheet XP
A1: Дней до порога XP — прогон типовых людей на НАСТОЯЩЕМ коде бота (economics/xp_simulator.py)
A3: v1.1 — после патча бота
A4: Профиль | B4: 100 · Житель | C4: 300 · Исследователь | D4: 800 · Проводник | E4: 2000 · Амбассадор | F4: 4000 · Легенда города | G4: 7000 · City Code
A5: Турист / редкий гость | B5: 119 | C5: 399 | D5: 1099 | E5: > 6 лет | F5: > 6 лет | G5: > 6 лет
A6: Житель: заходит 3 раза в неделю | B6: 37 | C6: 133 | D6: 365 | E6: 925 | F6: 1857 | G6: > 6 лет
A7: Активный: 5 дней в неделю, всё меню | B7: 10 | C7: 38 | D7: 108 | E7: 276 | F7: 556 | G7: 976
A8: Фармер кнопок: каждый день все 8 действий | B8: 8 | C8: 28 | D8: 78 | E8: 198 | F8: 398 | G8: 698
A9: Вкладчик города: активный + 2 места + 1 событие + 1 друг в месяц | B9: 3 | C9: 10 | D9: 43 | E9: 123 | F9: 246 | G9: 438
A10: Амбассадор: вкладчик + 4 места + 2 события + 3 друга в месяц | B10: 3 | C10: 10 | D10: 29 | E10: 78 | F10: 153 | G10: 273
A11: Партнёр-точка: житель + узел подключён (+200) и жив каждый месяц (+80) | B11: 3 | C11: 33 | D11: 123 | E11: 385 | F11: 793 | G11: 1413
A13: v1.0 — код бота до патча
A14: Профиль | B14: 100 · Житель | C14: 300 · Исследователь | D14: 800 · Проводник | E14: 2000 · Амбассадор | F14: 4000 · Легенда города | G14: 7000 · City Code
A15: Турист / редкий гость | B15: 84 | C15: 287 | D15: 784 | E15: 1988 | F15: > 6 лет | G15: > 6 лет
A16: Житель: заходит 3 раза в неделю | B16: 28 | C16: 93 | D16: 260 | E16: 660 | F16: 1325 | G16: > 6 лет
A17: Активный: 5 дней в неделю, всё меню | B17: 7 | C17: 25 | D17: 72 | E17: 184 | F17: 371 | G17: 651
A18: Фармер кнопок: каждый день все 8 действий | B18: 4 | C18: 13 | D18: 35 | E18: 90 | F18: 181 | G18: 317
A19: Вкладчик города: активный + 2 места + 1 событие + 1 друг в месяц | B19: 3 | C19: 10 | D19: 40 | E19: 112 | F19: 225 | G19: 396
A20: Амбассадор: вкладчик + 4 места + 2 события + 3 друга в месяц | B20: 3 | C20: 10 | D20: 29 | E20: 77 | F20: 152 | G20: 268
A21: Партнёр-точка: житель + узел подключён (+200) и жив каждый месяц (+80) | B21: 3 | C21: 28 | D21: 113 | E21: 329 | F21: 673 | G21: 1203

Sheet Доли партнёров
A1: Калькулятор долей: динамическая модель (Slicing Pie)
A2: Вклад считается по рыночной цене. Неоплаченное время и ресурсы ×2, живые деньги ×4 (риск выше). Доля = вклад участника / сумма вкладов. Итог — ориентир для переговоров, а не автоматическое решение.
A4: Участник | B4: Роль | C4: Неоплач. время, ₽/мес (рынок) | D4: Ресурсы, ₽/мес (аренда по рынку) | E4: Месяцев | F4: Разовый вклад (IP, оборудование), ₽ | G4: Деньги, ₽ | H4: Вклад (слайсы) | I4: Доля
A5: YuRich (основатель) | B5: Продукт, бренд, бот, база, сайт, продажи | C5: 150000 | D5: 0 | E5: 12 | F5: 1500000 | G5: 300000 | H5: =2*(C5+D5)*E5+2*F5+4*G5 | I5: =IF(SUM($H$5:$H$8)=0,0,H5/SUM($H$5:$H$8))
A6: Партнёр по оборудованию и контенту | B6: Камера, свет, звук, монтаж, съёмки | C6: 0 | D6: 40000 | E6: 12 | F6: 0 | G6: 0 | H6: =2*(C6+D6)*E6+2*F6+4*G6 | I6: =IF(SUM($H$5:$H$8)=0,0,H6/SUM($H$5:$H$8))
A7: Партнёр по событиям и офису | B7: Площадка для событий, рабочее место | C7: 0 | D7: 60000 | E7: 12 | F7: 0 | G7: 0 | H7: =2*(C7+D7)*E7+2*F7+4*G7 | I7: =IF(SUM($H$5:$H$8)=0,0,H7/SUM($H$5:$H$8))
A8: (резерв) Технический партнёр | B8: Разработка, сервер | C8: 0 | D8: 0 | E8: 0 | F8: 0 | G8: 0 | H8: =2*(C8+D8)*E8+2*F8+4*G8 | I8: =IF(SUM($H$5:$H$8)=0,0,H8/SUM($H$5:$H$8))
G9: Итого | H9: =SUM(H5:H8) | I9: =SUM(I5:I8)
A11: Ограничители (рекомендация)
A12: 1. Пул стратегических партнёров — не больше 10–15% на всех. Если калькулятор даёт больше — излишек платим revenue share, а не долей.
A13: 2. Вестинг 24–36 месяцев, первые 6–12 месяцев «клифф»: ушёл раньше — доли нет, вклад закрываем выплатами по выручке.
A14: 3. Доля возможна только в юрлице (ООО). Пока ты физлицо/ИП — опционный договор (ст. 429.2 ГК) или договор о выручке.
A15: 4. Доля — в той компании, где лежат права (товарные знаки, ПО, база). Не дробить на «долю в боте» и «долю в клубе».
A16: 5. Revenue share вместо доли: партнёру по оборудованию — 40% выручки со съёмок (= shoot_cost в params.json), площадке — 50% чистой выручки события.
